<?xml version="1.0" ?>
<!-- =================================================================================== -->
<!-- |    This document was autogenerated by xacro from src/boxxo_core/urdf/boxxo.urdf.xacro | -->
<!-- |    EDITING THIS FILE BY HAND IS NOT RECOMMENDED                                 | -->
<!-- =================================================================================== -->
<robot name="boxxo">
  <link name="base_link"/>
  <!-- The chassis of the rover -->
  <link name="chassie">
    <visual>
      <origin rpy="0 0 0" xyz="0 0 0.125"/>
      <geometry>
        <box size="1.6256 1.2446 0.25"/>
      </geometry>
    </visual>
    <collision>
      <origin rpy="0 0 0" xyz="0 0 0.125"/>
      <geometry>
        <box size="1.6256 1.2446 0.25"/>
      </geometry>
    </collision>
    <inertial>
      <origin rpy="0 0 0" xyz="0 0 0.125"/>
      <mass value="0"/>
      <inertia ixx="1.25" ixy="0.0" ixz="0.0" iyy="7.0" iyz="0.0" izz="0.0"/>
    </inertial>
  </link>
  <joint name="reality_glue" type="fixed">
    <parent link="base_link"/>
    <child link="chassie"/>
  </joint>
  <link name="front_left_wheel_link">
    <visual>
      <origin rpy="1.5707963267948966 0 0" xyz="0 0 0"/>
      <geometry>
        <cylinder length="0.1286" radius="0.3032"/>
      </geometry>
    </visual>
    <collision>
      <origin rpy="1.5707963267948966 0 0" xyz="0 0 0"/>
      <geometry>
        <cylinder length="0.1286" radius="0.3032"/>
      </geometry>
    </collision>
    <inertial>
      <origin rpy="1.5707963267948966 0 0" xyz="0 0 0"/>
      <mass value="35"/>
      <inertia ixx="0.08" ixy="0.0" ixz="0.0" iyy="0.14" iyz="0.0" izz="0.08"/>
    </inertial>
  </link>
  <joint name="front_left_wheel" type="continuous">
    <parent link="chassie"/>
    <child link="front_left_wheel_link"/>
    <origin rpy="0 0 0" xyz="0.8128 -0.6866 0.0625"/>
    <axis xyz="0 1 0"/>
  </joint>
  <transmission name="front_left_wheel_trans">
    <type>transmission_interface/SimpleTransmission</type>
    <joint name="front_left_wheel">
      <hardwareInterface>hardware_interface/VelocityJointInterface</hardwareInterface>
    </joint>
    <actuator>
      <hardwareInterface>hardware_interface/VelocityJointInterface</hardwareInterface>
      <mechanicalreduction>1</mechanicalreduction>
    </actuator>
  </transmission>
  <link name="front_right_wheel_link">
    <visual>
      <origin rpy="1.5707963267948966 0 0" xyz="0 0 0"/>
      <geometry>
        <cylinder length="0.1286" radius="0.3032"/>
      </geometry>
    </visual>
    <collision>
      <origin rpy="1.5707963267948966 0 0" xyz="0 0 0"/>
      <geometry>
        <cylinder length="0.1286" radius="0.3032"/>
      </geometry>
    </collision>
    <inertial>
      <origin rpy="1.5707963267948966 0 0" xyz="0 0 0"/>
      <mass value="35"/>
      <inertia ixx="0.08" ixy="0.0" ixz="0.0" iyy="0.14" iyz="0.0" izz="0.08"/>
    </inertial>
  </link>
  <joint name="front_right_wheel" type="continuous">
    <parent link="chassie"/>
    <child link="front_right_wheel_link"/>
    <origin rpy="0 0 0" xyz="0.8128 0.6866 0.0625"/>
    <axis xyz="0 1 0"/>
  </joint>
  <transmission name="front_right_wheel_trans">
    <type>transmission_interface/SimpleTransmission</type>
    <joint name="front_right_wheel">
      <hardwareInterface>hardware_interface/VelocityJointInterface</hardwareInterface>
    </joint>
    <actuator>
      <hardwareInterface>hardware_interface/VelocityJointInterface</hardwareInterface>
      <mechanicalreduction>1</mechanicalreduction>
    </actuator>
  </transmission>
  <link name="rear_left_wheel_link">
    <visual>
      <origin rpy="1.5707963267948966 0 0" xyz="0 0 0"/>
      <geometry>
        <cylinder length="0.1286" radius="0.3032"/>
      </geometry>
    </visual>
    <collision>
      <origin rpy="1.5707963267948966 0 0" xyz="0 0 0"/>
      <geometry>
        <cylinder length="0.1286" radius="0.3032"/>
      </geometry>
    </collision>
    <inertial>
      <origin rpy="1.5707963267948966 0 0" xyz="0 0 0"/>
      <mass value="35"/>
      <inertia ixx="0.08" ixy="0.0" ixz="0.0" iyy="0.14" iyz="0.0" izz="0.08"/>
    </inertial>
  </link>
  <joint name="rear_left_wheel" type="continuous">
    <parent link="chassie"/>
    <child link="rear_left_wheel_link"/>
    <origin rpy="0 0 0" xyz="-0.8128 -0.6866 0.0625"/>
    <axis xyz="0 1 0"/>
  </joint>
  <transmission name="rear_left_wheel_trans">
    <type>transmission_interface/SimpleTransmission</type>
    <joint name="rear_left_wheel">
      <hardwareInterface>hardware_interface/VelocityJointInterface</hardwareInterface>
    </joint>
    <actuator>
      <hardwareInterface>hardware_interface/VelocityJointInterface</hardwareInterface>
      <mechanicalreduction>1</mechanicalreduction>
    </actuator>
  </transmission>
  <link name="rear_right_wheel_link">
    <visual>
      <origin rpy="1.5707963267948966 0 0" xyz="0 0 0"/>
      <geometry>
        <cylinder length="0.1286" radius="0.3032"/>
      </geometry>
    </visual>
    <collision>
      <origin rpy="1.5707963267948966 0 0" xyz="0 0 0"/>
      <geometry>
        <cylinder length="0.1286" radius="0.3032"/>
      </geometry>
    </collision>
    <inertial>
      <origin rpy="1.5707963267948966 0 0" xyz="0 0 0"/>
      <mass value="35"/>
      <inertia ixx="0.08" ixy="0.0" ixz="0.0" iyy="0.14" iyz="0.0" izz="0.08"/>
    </inertial>
  </link>
  <joint name="rear_right_wheel" type="continuous">
    <parent link="chassie"/>
    <child link="rear_right_wheel_link"/>
    <origin rpy="0 0 0" xyz="-0.8128 0.6866 0.0625"/>
    <axis xyz="0 1 0"/>
  </joint>
  <transmission name="rear_right_wheel_trans">
    <type>transmission_interface/SimpleTransmission</type>
    <joint name="rear_right_wheel">
      <hardwareInterface>hardware_interface/VelocityJointInterface</hardwareInterface>
    </joint>
    <actuator>
      <hardwareInterface>hardware_interface/VelocityJointInterface</hardwareInterface>
      <mechanicalreduction>1</mechanicalreduction>
    </actuator>
  </transmission>
</robot>
